Workbook
Name UPDATE: 'Data Sheet'!$E$1

Sheet  Model>

Sheet 3 Statement Model
C2: Historical Data | H2: Forecast Period
C3: ='Historical FS'!H3 -> 44651 | D3: ='Historical FS'!I3 -> 45016 | E3: ='Historical FS'!J3 -> 45382 | F3: ='Historical FS'!K3 -> 45747 | G3: ='Historical FS'!L3 -> 46112 | H3: =G3+365 -> 46477 | I3: =H3+365 -> 46842 | J3: =I3+365 -> 47207 | K3: =J3+365 -> 47572 | L3: =K3+365 -> 47937
B4: Balance Sheet Check | C4: =IF(C46=C59,"True","False") -> True | D4: =IF(D46=D59,"True","False") -> True | E4: =IF(E46=E59,"True","False") -> True | F4: =IF(F46=F59,"True","False") -> True | G4: =IF(G46=G59,"True","False") -> True | H4: =IF(H46=H59,"True","False") -> True | I4: =IF(I46=I59,"True","False") -> True | J4: =IF(J46=J59,"True","False") -> True | ... L4: =IF(L46=L59,"True","False") -> True
A6: # | B6: Assumptions
B7: Sales (% Growth) | D7: =D27/C27-1 -> 0.20655864 | E7: =E27/D27-1 -> 0.047033734 | F7: =F27/E27-1 -> 0.060649444 | G7: =G27/F27-1 -> 0.096079514 | H7: 0.106 | I7: 0.106 | J7: 0.106 | K7: 0.106 | L7: 0.106
B8: COGS (% Revenue | C8: =C28/C27 -> 0.69728957 | D8: =D28/D27 -> 0.71460206 | E8: =E28/E27 -> 0.71601484 | F8: =F28/F27 -> 0.71528928 | G8: =G28/G27 -> 0.71792331 | H8: 0.7122 | I8: 0.7122 | J8: 0.7122 | K8: 0.7122 | L8: 0.7122
B9: Selling & Adm Expense(% Revenue) | C9: =C30/C27 -> 0.043825684 | D9: =D30/D27 -> 0.04603896 | E9: =E30/E27 -> 0.046951259 | F9: =F30/F27 -> 0.043984294 | G9: =G30/G27 -> 0.045412818 | H9: 0.0452 | I9: 0.0452 | J9: 0.0452 | K9: 0.0452 | L9: 0.0452
B10: Other Income % Of Revenue | C10: =C32/C27 -> 0.018866994 | D10: =D32/D27 -> 0.01840332 | E10: =E32/E27 -> 0.030656602 | F10: =F32/F27 -> 0.022087245 | G10: =G32/G27 -> 0.01697733 | H10: 0.021 | I10: 0.021 | J10: 0.021 | K10: 0.021 | L10: 0.021
B11: Depreciation | C11: =C34/(C48+C49) -> 0.13259078 | D11: =D34/(D48+D49) -> 0.14315725 | E11: =E34/(E48+E49) -> 0.16758015 | F11: =F34/(F48+F49) -> 0.15143981 | G11: =G34/(G48+G49) -> 0.14293212 | H11: 0.1475 | I11: 0.1475 | J11: 0.1475 | K11: 0.1475 | L11: 0.1475
B12: Interest | C12: =C35/C44 -> 0.036536354 | D12: =D35/D44 -> 0.03422099 | E12: =E35/E44 -> 0.056226821 | F12: =F35/F44 -> 0.050565212 | G12: =G35/G44 -> 0.045335658 | H12: 0.045 | I12: 0.045 | J12: 0.045 | K12: 0.045 | L12: 0.045
B13: Tax (% EBT | C13: =C37/C36 -> 0.26449684 | D13: =D37/D36 -> 0.27651401 | E13: =E37/E36 -> 0.27064577 | F13: =F37/F36 -> 0.28871517 | G13: =G37/G36 -> 0.26305788 | H13: 0.2727 | I13: 0.2727 | J13: 0.2727 | K13: 0.2727 | L13: 0.2727
B14: Accounts Receivables (days) | C14: =C54/C27*C24 -> 68.108368 | D14: =D54/D27*D24 -> 63.227837 | E14: =E54/E27*E24 -> 71.715006 | F14: =F54/F27*F24 -> 69.775262 | G14: =G54/G27*G24 -> 71.986622 | H14: 68 | I14: 68 | J14: 68 | K14: 68 | L14: 68
B15: Inventory (days) | C15: =C55/C27*C24 -> 0 | D15: =D55/D27*D24 -> 0 | E15: =E55/E27*E24 -> 0 | F15: =F55/F27*F24 -> 0 | G15: =G55/G27*G24 -> 0 | H15: 0 | I15: 0 | J15: 0 | K15: 0 | L15: 0
B16: Accounts Payables (days) | C16: =C44/C27*C24 -> 16.425465 | D16: =D44/D27*D24 -> 20.639074 | E16: =E44/E27*E24 -> 19.854461 | F16: =F44/F27*F24 -> 18.423554 | G16: =G44/G27*G24 -> 18.747495 | H16: 18 | I16: 18 | J16: 18 | K16: 18 | L16: 18
B17: Capex % of Revenue | C17: =C96/C27 -> 0.03100106 | D17: =D96/D27 -> 0.052123434 | E17: =E96/E27 -> 0.020010412 | F17: =F96/F27 -> 0.050009203 | G17: =G96/G27 -> 0.043162608 | H17: 0.04 | I17: 0.04 | J17: 0.04 | K17: 0.04 | L17: 0.04
B18: CWIP | C18: =C49 -> 416 | D18: =D49 -> 288 | E18: =E49 -> 293 | F18: =F49 -> 814 | G18: =G49 -> 526 | H18: 467 | I18: 467 | J18: 467 | K18: 467 | L18: 467
B19: Other Liabilities % Of Revenue | C19: =C45/C27 -> 0.29517186 | D19: =D45/D27 -> 0.27860486 | E19: =E45/E27 -> 0.25733715 | F19: =F45/F27 -> 0.26842138 | G19: =G45/G27 -> 0.29252729 | H19: 0.2784 | I19: 0.2784 | J19: 0.2784 | K19: 0.2784 | L19: 0.2784
B20: Other Non Current Assets % Of Revenue | C20: =C51/C27 -> 0.24678357 | D20: =D51/D27 -> 0.2589683 | E20: =E51/E27 -> 0.25055639 | F20: =F51/F27 -> 0.22618566 | G20: =G51/G27 -> 0.22769102 | H20: 0.23 | I20: 0.23 | J20: 0.23 | K20: 0.23 | L20: 0.23
B21: Investment Growth Rate | D21: =D50/C50-1 -> -0.041625664 | E21: =E50/D50-1 -> 0.26414416 | F21: =F50/E50-1 -> -0.043942655 | G21: =G50/F50-1 -> -0.07055775 | H21: 0.027 | I21: 0.027 | J21: 0.027 | K21: 0.027 | L21: 0.027
B22: Equity Share Capital | C22: =C42 -> 2098 | D22: =D42 -> 2069 | E22: =E42 -> 2071 | F22: =F42 -> 2073 | G22: =G42 -> 2024 | H22: 2024 | I22: 2024 | J22: 2024 | K22: 2024 | L22: 2024
B23: Dividend Payout Ratio | D23: =D112 -> 0.0035672806 | E23: =E112 -> 0.48411308 | F23: =F112 -> 0.28785047 | G23: =G112 -> -0.098968582 | H23: 0.1691 | I23: 0.1691 | J23: 0.1691 | K23: 0.1691 | L23: 0.1691
B24: Period | C24: 365 | D24: 365 | E24: 365 | F24: 365 | G24: 365 | H24: 365 | I24: 365 | J24: 365 | K24: 365 | L24: 365
A26: # | B26: Income Statement
B27: Sales | C27: 121641 | D27: 146767 | E27: 153670 | F27: 162990 | G27: 178650 | H27: =G27*(1+H7) -> 197586.9 | I27: =H27*(1+I7) -> 218531.11 | J27: =I27*(1+J7) -> 241695.41 | K27: =J27*(1+K7) -> 267315.12 | L27: =K27*(1+L7) -> 295650.53
B28: COGS | C28: 84819 | D28: 104880 | E28: 110030 | F28: 116585 | G28: 128257 | H28: =H27*H8 -> 140721.39 | I28: =I27*I8 -> 155637.86 | J28: =J27*J8 -> 172135.47 | K28: =K27*K8 -> 190381.83 | L28: =L27*L8 -> 210562.3
B29: Gross Profits | C29: =C27-C28 -> 36822 | D29: =D27-D28 -> 41887 | E29: =E27-E28 -> 43640 | F29: =F27-F28 -> 46405 | G29: =G27-G28 -> 50393 | H29: =H27-H28 -> 56865.51 | I29: =I27-I28 -> 62893.254 | J29: =J27-J28 -> 69559.939 | ... L29: =L27-L28 -> 85088.221
B30: Selling & Adm Expense | C30: 5331 | D30: 6757 | E30: 7215 | F30: 7169 | G30: 8113 | H30: =H27*H9 -> 8930.9279 | I30: =I27*I9 -> 9877.6062 | J30: =J27*J9 -> 10924.632 | K30: =K27*K9 -> 12082.644 | L30: =L27*L9 -> 13363.404
B31: EBITDA | C31: =C29-C30 -> 31491 | D31: =D29-D30 -> 35130 | E31: =E29-E30 -> 36425 | F31: =F29-F30 -> 39236 | G31: =G29-G30 -> 42280 | H31: =H29-H30 -> 47934.582 | I31: =I29-I30 -> 53015.648 | J31: =J29-J30 -> 58635.306 | ... L31: =L29-L30 -> 71724.818
B32: Other Income | C32: 2295 | D32: 2701 | E32: 4711 | F32: 3600 | G32: 3033 | H32: =H27*H10 -> 4149.3249 | I32: =I27*I10 -> 4589.1533 | J32: =J27*J10 -> 5075.6036 | K32: =K27*K10 -> 5613.6176 | L32: =L27*L10 -> 6208.661
B33: Expenses
B34: Depreciation | C34: 3476 | D34: 4225 | E34: 4678 | F34: 4812 | G34: 4902 | H34: =H97 -> 4981.075 | I34: =I97 -> 5412.1291 | J34: =J97 -> 5903.1737 | K34: =K97 -> 6458.4585 | L34: =L97 -> 7082.9951
B35: Interest | C35: 200 | D35: 284 | E35: 470 | F35: 416 | G35: 416 | H35: =H104 -> 412.92 | I35: =I104 -> 438.48052 | J35: =J104 -> 484.95945 | K35: =K104 -> 536.36515 | L35: =L104 -> 593.21986
B36: EBT | C36: =C31+C32-(C34+C35) -> 30110 | D36: =D31+D32-(D34+D35) -> 33322 | E36: =E31+E32-(E34+E35) -> 35988 | F36: =F31+F32-(F34+F35) -> 37608 | G36: =G31+G32-(G34+G35) -> 39995 | H36: =H31+H32-(H34+H35) -> 46689.912 | I36: =I31+I32-(I34+I35) -> 51754.191 | J36: =J31+J32-(J34+J35) -> 57322.777 | ... L36: =L31+L32-(L34+L35) -> 70257.264
B37: Tax | C37: 7964 | D37: 9214 | E37: 9740 | F37: 10858 | G37: 10521 | H37: =H36*H13 -> 12732.339 | I37: =I36*I13 -> 14113.368 | J37: =J36*J13 -> 15631.921 | K37: =K36*K13 -> 17308.117 | L37: =L36*L13 -> 19159.156
B38: Net Profits | C38: =C36-C37 -> 22146 | D38: =D36-D37 -> 24108 | E38: =E36-E37 -> 26248 | F38: =F36-F37 -> 26750 | G38: =G36-G37 -> 29474 | H38: =H36-H37 -> 33957.573 | I38: =I36-I37 -> 37640.823 | J38: =J36-J37 -> 41690.856 | ... L38: =L36-L37 -> 51098.108
A41: # | B41: Balance Sheet
B42: Equity Share Capital | C42: 2098 | D42: 2069 | E42: 2071 | F42: 2073 | G42: 2024 | H42: =H22 -> 2024 | I42: =I22 -> 2024 | J42: =J22 -> 2024 | K42: =K22 -> 2024 | L42: =L22 -> 2024
B43: Reserves | C43: 73252 | D43: 73338 | E43: 86045 | F43: 93745 | G43: 90828 | H43: =H111 -> 119043.35 | I43: =I111 -> 150319.11 | J43: =J111 -> 184960.04 | K43: =K111 -> 223315.48 | L43: =L111 -> 265772.9
B44: Borrowings | C44: 5474 | D44: 8299 | E44: 8359 | F44: 8227 | G44: 9176 | H44: =H27*H16/H24 -> 9744.0115 | I44: =I27*I16/I24 -> 10776.877 | J44: =J27*J16/J24 -> 11919.226 | K44: =K27*K16/K24 -> 13182.664 | L44: =L27*L16/L24 -> 14580.026
B45: Other Liabilities | C45: 35905 | D45: 40890 | E45: 39545 | F45: 43750 | G45: 52260 | H45: =G45*(1+H19) -> 66809.184 | I45: =H45*(1+I19) -> 85408.861 | J45: =I45*(1+J19) -> 109186.69 | K45: =J45*(1+K19) -> 139584.26 | L45: =K45*(1+L19) -> 178444.52
...

Sheet Relative Valuation
B2: Comparable Company Valuation
B3: S.No. | C3: Name | D3: Share Price | E3: No. Eq. Shares | F3: Equity Value | G3: Enterprise Value | H3: Net Debt | I3: Revenue | J3: EBITDA | K3: Net Profit | L3: EV/Revenue | M3: EV / EBITDA | N3: P/E
B4: 1 | C4: TCS | D4: 2287 | E4: 361.81 | F4: =D4*E4 -> 827459.47 | G4: 825831.66 | H4: =G4-F4 -> -1627.81 | I4: 275859 | J4: =G4/M4 -> 78352.15 | K4: 78389 | L4: =G4/I4 -> 2.9936731 | M4: 10.54 | N4: =F4/K4 -> 10.555811
B5: 2 | C5: Infosys | D5: 1115.3 | E5: 405.81 | F5: =D5*E5 -> 452599.89 | G5: 439687.04 | H5: =G5-F5 -> -12912.853 | I5: 184582 | J5: =G5/M5 -> 48000.769 | K5: 48009 | L5: =G5/I5 -> 2.3820689 | M5: 9.16 | N5: =F5/K5 -> 9.4273968
B6: 3 | C6: HCL Technologies | D6: 1298.9 | E6: 271.37 | F6: =D6*E6 -> 352482.49 | G6: 334267.96 | H6: =G6-F6 -> -18214.533 | I6: 134374 | J6: =G6/M6 -> 29016.316 | K6: 29022 | L6: =G6/I6 -> 2.487594 | M6: 11.52 | N6: =F6/K6 -> 12.145355
B7: 4 | C7: Tech Mahindra | D7: 1586 | E7: 98.01 | F7: =D7*E7 -> 155443.86 | G7: 152522.27 | H7: =G7-F7 -> -2921.59 | I7: 59176.1 | J7: =G7/M7 -> 9544.5726 | K7: 9542.3 | L7: =G7/I7 -> 2.5774302 | M7: 15.98 | N7: =F7/K7 -> 16.289978
B8: 5 | C8: Wipro | D8: 179.15 | E8: 990.45 | F8: =D8*E8 -> 177439.12 | G8: 187175.3 | H8: =G8-F8 -> 9736.1825 | I8: 94968 | J8: =G8/M8 -> 22020.624 | K8: 22017.7 | L8: =G8/I8 -> 1.9709302 | M8: 8.5 | N8: =F8/K8 -> 8.0589307
B9: 6 | C9: LTM | D9: 4637.5 | E9: 29.66 | F9: =D9*E9 -> 137548.25 | G9: 137055.72 | H9: =G9-F9 -> -492.53 | I9: 44075 | J9: =G9/M9 -> 8922.8984 | K9: 8924.1 | L9: =G9/I9 -> 3.1096023 | M9: 15.36 | N9: =F9/K9 -> 15.413123
B10: 7 | C10: Presistent System | D10: 5520.15 | E10: 15.78 | F10: =D10*E10 -> 87107.967 | G10: 86339.56 | H10: =G10-F10 -> -768.407 | I10: 15718.1 | J10: =G10/M10 -> 3076.9622 | K10: 3077.15 | L10: =G10/I10 -> 5.4930023 | M10: 28.06 | N10: =F10/K10 -> 28.308002
B12: High | L12: =MAX(L4:L10) -> 5.4930023 | M12: =MAX(M4:M10) -> 28.06 | N12: =MAX(N4:N10) -> 28.308002
B13: 75th Percentile | L13: =QUARTILE(L4:L10,3) -> 3.0516377 | M13: =QUARTILE(M4:M10,3) -> 15.67 | N13: =QUARTILE(N4:N10,3) -> 15.851551
B14: Average | L14: =AVERAGE(L4:L10) -> 3.002043 | M14: =AVERAGE(M4:M10) -> 14.16 | N14: =AVERAGE(N4:N10) -> 14.314085
B15: Median | L15: =MEDIAN(L4:L10) -> 2.5774302 | M15: =MEDIAN(M4:M10) -> 11.52 | N15: =MEDIAN(N4:N10) -> 12.145355
B16: 25th Percentile | L16: =QUARTILE(L4:L10,1) -> 2.4348315 | M16: =QUARTILE(M4:M10,1) -> 9.85 | N16: =QUARTILE(N4:N10,1) -> 9.9916039
B17: Low | L17: =MIN(L4:L10) -> 1.9709302 | M17: =MIN(M4:M10) -> 8.5 | N17: =MIN(N4:N10) -> 8.0589307
B19: Comparable Valuation
B20: Implied Enterprise Value | L20: =L15*I5 -> 475747.23 | M20: =M15*J5 -> 552968.85 | N20: =N22+N21 -> 570173.5
B21: Net Debt | L21: =$H$5 -> -12912.853 | M21: =$H$5 -> -12912.853 | N21: =$H$5 -> -12912.853
B22: Implied Market Value | L22: =L20-L21 -> 488660.08 | M22: =M20-M21 -> 565881.71 | N22: =N15*K5 -> 583086.35
B23: No. Of Shares | L23: =$E$5 -> 405.81 | M23: =$E$5 -> 405.81 | N23: =$E$5 -> 405.81
B24: Implied Value of Shares | L24: =L22/L23 -> 1204.1598 | M24: =M22/M23 -> 1394.4499 | N24: =N22/N23 -> 1436.8457
L25: =IF(L24>$D$5,"Undervalued","Overvalued") -> Undervalued | M25: =IF(M24>$D$5,"Undervalued","Overvalued") -> Undervalued | N25: =IF(N24>$D$5,"Undervalued","Overvalued") -> Undervalued
B27: 1) Financial data is sourced from the Screener.in.
B28: 2) Minor differences may exist due to rounding of reported figures.
B29: 3) All figures are presented in Rupee Corores

Sheet DCF Valuation Model
B2: Unlevered Cash Flow
B3: Fiscal Year | F3: ='3 Statement Model'!G3 -> 46112 | G3: ='3 Statement Model'!H3 -> 46477 | H3: ='3 Statement Model'!I3 -> 46842 | I3: ='3 Statement Model'!J3 -> 47207 | J3: ='3 Statement Model'!K3 -> 47572 | K3: ='3 Statement Model'!L3 -> 47937
B4: Sales | F4: ='3 Statement Model'!G27 -> 178650 | G4: ='3 Statement Model'!H27 -> 197586.9 | H4: ='3 Statement Model'!I27 -> 218531.11 | I4: ='3 Statement Model'!J27 -> 241695.41 | J4: ='3 Statement Model'!K27 -> 267315.12 | K4: ='3 Statement Model'!L27 -> 295650.53
B5: COGS | F5: ='3 Statement Model'!G28 -> 128257 | G5: ='3 Statement Model'!H28 -> 140721.39 | H5: ='3 Statement Model'!I28 -> 155637.86 | I5: ='3 Statement Model'!J28 -> 172135.47 | J5: ='3 Statement Model'!K28 -> 190381.83 | K5: ='3 Statement Model'!L28 -> 210562.3
B6: Gross Profits | F6: =F4-F5 -> 50393 | G6: =G4-G5 -> 56865.51 | H6: =H4-H5 -> 62893.254 | I6: =I4-I5 -> 69559.939 | J6: =J4-J5 -> 76933.292 | K6: =K4-K5 -> 85088.221
B7: Selling & Adm Expense | F7: ='3 Statement Model'!G30 -> 8113 | G7: ='3 Statement Model'!H30 -> 8930.9279 | H7: ='3 Statement Model'!I30 -> 9877.6062 | I7: ='3 Statement Model'!J30 -> 10924.632 | J7: ='3 Statement Model'!K30 -> 12082.644 | K7: ='3 Statement Model'!L30 -> 13363.404
B8: EBITDA | F8: =F6-F7 -> 42280 | G8: =G6-G7 -> 47934.582 | H8: =H6-H7 -> 53015.648 | I8: =I6-I7 -> 58635.306 | J8: =J6-J7 -> 64850.649 | K8: =K6-K7 -> 71724.818
B9: Other Income | F9: ='3 Statement Model'!G32 -> 3033 | G9: ='3 Statement Model'!H32 -> 4149.3249 | H9: ='3 Statement Model'!I32 -> 4589.1533 | I9: ='3 Statement Model'!J32 -> 5075.6036 | J9: ='3 Statement Model'!K32 -> 5613.6176 | K9: ='3 Statement Model'!L32 -> 6208.661
B10: Operating Expenses
B11: Depreciation | F11: ='3 Statement Model'!G34 -> 4902 | G11: ='3 Statement Model'!H34 -> 4981.075 | H11: ='3 Statement Model'!I34 -> 5412.1291 | I11: ='3 Statement Model'!J34 -> 5903.1737 | J11: ='3 Statement Model'!K34 -> 6458.4585 | K11: ='3 Statement Model'!L34 -> 7082.9951
B12: EBIT | F12: =F8+F9-F11 -> 40411 | G12: =G8+G9-G11 -> 47102.832 | H12: =H8+H9-H11 -> 52192.672 | I12: =I8+I9-I11 -> 57807.736 | J12: =J8+J9-J11 -> 64005.808 | K12: =K8+K9-K11 -> 70850.483
B13: Tax | F13: ='3 Statement Model'!G37 -> 10521 | G13: ='3 Statement Model'!H37 -> 12732.339 | H13: ='3 Statement Model'!I37 -> 14113.368 | I13: ='3 Statement Model'!J37 -> 15631.921 | J13: ='3 Statement Model'!K37 -> 17308.117 | K13: ='3 Statement Model'!L37 -> 19159.156
B14: NOPAT | F14: =F12-F13 -> 29890 | G14: =G12-G13 -> 34370.493 | H14: =H12-H13 -> 38079.304 | I14: =I12-I13 -> 42175.815 | J14: =J12-J13 -> 46697.691 | K14: =K12-K13 -> 51691.328
B15: Add. Depreciation | F15: =F11 -> 4902 | G15: =G11 -> 4981.075 | H15: =H11 -> 5412.1291 | I15: =I11 -> 5903.1737 | J15: =J11 -> 6458.4585 | K15: =K11 -> 7082.9951
B16: Less. Capex | F16: ='3 Statement Model'!G96 -> 7711 | G16: ='3 Statement Model'!H96 -> 7903.476 | H16: ='3 Statement Model'!I96 -> 8741.2445 | I16: ='3 Statement Model'!J96 -> 9667.8164 | J16: ='3 Statement Model'!K96 -> 10692.605 | K16: ='3 Statement Model'!L96 -> 11826.021
B17: Less. Change in NWC | F17: ='3 Statement Model'!G91 -> 3127 | G17: ='3 Statement Model'!H91 -> 1008.6986 | H17: ='3 Statement Model'!I91 -> 2869.0701 | I17: ='3 Statement Model'!J91 -> 3173.1915 | J17: ='3 Statement Model'!K91 -> 3509.5498 | K17: ='3 Statement Model'!L91 -> 3881.5621
B18: Net Working Capital | F18: ='3 Statement Model'!G90 -> 26058 | G18: ='3 Statement Model'!H90 -> 27066.699 | H18: ='3 Statement Model'!I90 -> 29935.769 | I18: ='3 Statement Model'!J90 -> 33108.96 | J18: ='3 Statement Model'!K90 -> 36618.51 | K18: ='3 Statement Model'!L90 -> 40500.072
B19: Unlevered Cash Flow | F19: =F14+F15-F16-F17 -> 23954 | G19: =G14+G15-G16-G17 -> 30439.393 | H19: =H14+H15-H16-H17 -> 31881.118 | I19: =I14+I15-I16-I17 -> 35237.981 | J19: =J14+J15-J16-J17 -> 38953.995 | K19: =K14+K15-K16-K17 -> 43066.74
B20: Projection Year | G20: 1 | H20: 2 | I20: 3 | J20: 4 | K20: 5
B21: Discounting Factor | G21: =1/(1+$D$26)^G20 -> 0.89834075 | H21: =1/(1+$D$26)^H20 -> 0.8070161 | I21: =1/(1+$D$26)^I20 -> 0.72497545 | J21: =1/(1+$D$26)^J20 -> 0.65127499 | K21: =1/(1+$D$26)^K20 -> 0.58506687
B22: PV Of FCFF | G22: =G19*G21 -> 27344.947 | H22: =H19*H21 -> 25728.576 | I22: =I19*I21 -> 25546.671 | J22: =J19*J21 -> 25369.763 | K22: =K19*K21 -> 25196.922
B24: Expected Growth | D24: 0.106
B25: Terminal Growth | D25: 0.045
B26: WACC | D26: =WACC!J34 -> 0.11316335
B28: Calculation Of Terminal Value | G28: Calculation Of Value Of Operating Assets
B29: WACC | E29: =D26 -> 0.11316335 | G29: Sum Of PV Of FCFF | K29: =SUM(G22:K22) -> 129186.88
B30: Terminal Growth | E30: =D25 -> 0.045 | G30: PV Of Terminal Value | K30: =E32*K21 -> 386289.46
B32: Terminal Value | E32: =K19*(1+E30)/(E29-E30) -> 660248.4 | G32: Value Of Operating Assets | K32: =K29+K30 -> 515476.34
B34: Equity Value Per Share | H34: Sensitivity Analysis
G35: =E40 -> 1302.3509 | H35: 0.1 | I35: 0.1075 | J35: 0.1132 | K35: 0.12
B36: Add : Cash | E36: ='Data Sheet'!K69 -> 22201 | G36: 0.025 | H36: 1199.0218 | I36: 1121.8783 | J36: 1072.0237 | K36: 1020.3737
B37: Less: Debt | E37: ='Data Sheet'!K59 -> 9176 | G37: 0.035 | H37: 1339.1248 | I37: 1236.8474 | J37: 1172.2374 | K37: 1106.4939
B38: Value Of Equity | E38: =K32+E36-E37 -> 528501.34 | G38: 0.045 | H38: 1530.1744 | I38: 1388.6066 | J38: 1301.8393 | K38: 1215.5794
B39: No. Of Shares | E39: ='Data Sheet'!B6 -> 405.80565 | G39: 0.055 | H39: 1806.1349 | I39: 1598.1789 | J39: 1475.978 | K39: 1358.2298
B40: Equity Value Per Share | E40: =E38/E39 -> 1302.3509 | G40: 0.065 | H40: 2239.787 | I40: 1906.3734 | J40: 1722.3734 | K40: 1552.753

Sheet WACC
B5: Weighted Average Cost Of Capital
B6: All The Figures Are in INR Unless Stated Otherwise
B7: Peer Comps
G8: Debt/ | H8: Debt/ | I8: Levered | J8: Unlevered
B9: Name of the Company | C9: Country | D9: Total Debt | E9: Market Capitalisation | F9: Tax rate 1 | G9: Equity | H9: Capital | I9: Beta 2 | J9: Beta 3
B10: Infosys | C10: India | D10: 8737 | E10: 452250.12 | F10: 0.3 | G10: =D10/E10 -> 0.019318956 | H10: =D10/SUM(D10,E10) -> 0.018952807 | I10: 0.75 | J10: =I10/(1+(1-F10)*G10) -> 0.73999288
B11: TCS | C11: India | D11: 11283 | E11: 826588.33 | F11: 0.3 | G11: =D11/E11 -> 0.013650084 | H11: =D11/SUM(D11,E11) -> 0.013466268 | I11: 0.7 | J11: =I11/(1+(1-F11)*G11) -> 0.69337476
B12: HCL Technologies | C12: India | D12: 5215 | E12: 351962.37 | F12: 0.3 | G12: =D12/E12 -> 0.014816925 | H12: =D12/SUM(D12,E12) -> 0.014600589 | I12: 0.8 | J12: =I12/(1+(1-F12)*G12) -> 0.7917877
B13: Wipro | C13: India | D13: 20291 | E13: 177736.91 | F13: 0.3 | G13: =D13/E13 -> 0.11416312 | H13: =D13/SUM(D13,E13) -> 0.10246535 | I13: 0.85 | J13: =I13/(1+(1-F13)*G13) -> 0.78709958
E14: Average | F14: =AVERAGE(F10:F13) -> 0.3 | G14: =AVERAGE(G10:G13) -> 0.040487271 | H14: =AVERAGE(H10:H13) -> 0.037371255 | I14: =AVERAGE(I10:I13) -> 0.775 | J14: =AVERAGE(J10:J13) -> 0.75306373
E15: Median | F15: =MEDIAN(F10:F13) -> 0.3 | G15: =MEDIAN(G10:G13) -> 0.01706794 | H15: =MEDIAN(H10:H13) -> 0.016776698 | I15: =MEDIAN(I10:I13) -> 0.775 | J15: =MEDIAN(J10:J13) -> 0.76354623
B17: Cost of Debt | G17: Cost of Equity
B19: Pre tax cost of debt | E19: ='Data Sheet'!K27/'Data Sheet'!K59 -> 0.045335658 | G19: Riskfree rate | J19: 0.0676
B20: Tax rate | E20: 0.2727 | G20: Equity risk premium | J20: 0.062
B21: Post tax cost of debt | E21: =E19*(1-E20) -> 0.032972624 | G21: Levered beta 4 | J21: =E28 -> 0.78510519
G22: Cost of equity | J22: =J19+(J20*J21) -> 0.11627652
B23: Levered beta
G24: Cost of Debt
B25: Comps median unlevered beta | E25: =J15 -> 0.76354623 | I25: Current | J25: Target
B26: Target debt/equity | E26: =E30 -> 0.038822085 | G26: Total debt | H26: =D10 -> 8737 | I26: =H26/H28 -> 0.018952807 | J26: =H14 -> 0.037371255
B27: Tax rate | E27: =E20 -> 0.2727 | G27: Market Capitalization | H27: =E10 -> 452250.12 | I27: =H27/H28 -> 0.98104719 | J27: =J28-J26 -> 0.96262875
B28: Levered beta | E28: =E25*(1+(1-E27)*E26) -> 0.78510519 | G28: Total Capital | H28: =H26+H27 -> 460987.12 | I28: =H28/H28 -> 1 | J28: =I28 -> 1
B30: Debt/Equity | D30: =I26/I27 -> 0.019318956 | E30: =J26/J27 -> 0.038822085 | G30: Weighted average cost of capital
I31: Total cost | J31: Total weight
B32: Note: | G32: Debt | I32: =E21 -> 0.032972624 | J32: =J26 -> 0.037371255
B33: 1. Tax rate considered as marginal tax rate for country | G33: Equity | I33: =J22 -> 0.11627652 | J33: =J27 -> 0.96262875
B34: 2. Levered beta is based on 5 years monthly data | G34: Weighted average cost of capital | J34: =SUMPRODUCT(I32:I33,J32:J33) -> 0.11316335
B35: 3. Unlevered beta = levered beta/1+(1-tax rate)*debt/equity)
B36: 4. levered beta = unlevered beta*1+(1-tax rate)*debt/equity)

Sheet Football Field Anaylsis
B2: Football Field Analysis
J4: Data | K4: Data
L5: OpenLow | M5: Low | N5: OpenHigh | O5: High
K6: Comps | L6: ='Relative Valuation'!$L$24 -> 1204.1598 | M6: ='Relative Valuation'!$L$24 -> 1204.1598 | N6: ='Relative Valuation'!$N$24 -> 1436.8457 | O6: ='Relative Valuation'!$N$24 -> 1436.8457
K7: DCF Bear | L7: ='DCF Valuation Model'!$K$36 -> 1020.3737 | M7: ='DCF Valuation Model'!$K$36 -> 1020.3737 | N7: ='DCF Valuation Model'!$K$40 -> 1552.753 | O7: ='DCF Valuation Model'!$K$40 -> 1552.753
K8: DCF Base | L8: ='DCF Valuation Model'!$J$36 -> 1072.0237 | M8: ='DCF Valuation Model'!$J$36 -> 1072.0237 | N8: ='DCF Valuation Model'!$J$40 -> 1722.3734 | O8: ='DCF Valuation Model'!$J$40 -> 1722.3734
K9: DCF Bull | L9: ='DCF Valuation Model'!$H$36 -> 1199.0218 | M9: ='DCF Valuation Model'!$H$36 -> 1199.0218 | N9: ='DCF Valuation Model'!$H$40 -> 2239.787 | O9: ='DCF Valuation Model'!$H$40 -> 2239.787
K10: 52W H/L | L10: 982.4 | M10: 982.4 | N10: 1728 | O10: 1728

Sheet Financials>

Sheet Common Size Statement
B2: ="Common Size Income Statement"& "-" &'Data Sheet'!B1 -> Common Size Income Statement-INFOSYS LTD
B4: Particulars | C4: ='Data Sheet'!B16 -> 42825 | D4: ='Data Sheet'!C16 -> 43190 | E4: ='Data Sheet'!D16 -> 43555 | F4: ='Data Sheet'!E16 -> 43921 | G4: ='Data Sheet'!F16 -> 44286 | H4: ='Data Sheet'!G16 -> 44651 | I4: ='Data Sheet'!H16 -> 45016 | J4: ='Data Sheet'!I16 -> 45382 | ... L4: ='Data Sheet'!K16 -> 46112
B6: Sales | C6: =IFERROR('Data Sheet'!B17/'Data Sheet'!B$17,0) -> 1 | D6: =IFERROR('Data Sheet'!C17/'Data Sheet'!C$17,0) -> 1 | E6: =IFERROR('Data Sheet'!D17/'Data Sheet'!D$17,0) -> 1 | F6: =IFERROR('Data Sheet'!E17/'Data Sheet'!E$17,0) -> 1 | G6: =IFERROR('Data Sheet'!F17/'Data Sheet'!F$17,0) -> 1 | H6: =IFERROR('Data Sheet'!G17/'Data Sheet'!G$17,0) -> 1 | I6: =IFERROR('Data Sheet'!H17/'Data Sheet'!H$17,0) -> 1 | J6: =IFERROR('Data Sheet'!I17/'Data Sheet'!I$17,0) -> 1 | ... L6: =IFERROR('Data Sheet'!K17/'Data Sheet'!K$17,0) -> 1
B7: Raw Material Cost | C7: =IFERROR('Data Sheet'!B18/'Data Sheet'!B$17,0) -> 0 | D7: =IFERROR('Data Sheet'!C18/'Data Sheet'!C$17,0) -> 0 | E7: =IFERROR('Data Sheet'!D18/'Data Sheet'!D$17,0) -> 0 | F7: =IFERROR('Data Sheet'!E18/'Data Sheet'!E$17,0) -> 0 | G7: =IFERROR('Data Sheet'!F18/'Data Sheet'!F$17,0) -> 0 | H7: =IFERROR('Data Sheet'!G18/'Data Sheet'!G$17,0) -> 0 | I7: =IFERROR('Data Sheet'!H18/'Data Sheet'!H$17,0) -> 0 | J7: =IFERROR('Data Sheet'!I18/'Data Sheet'!I$17,0) -> 0 | ... L7: =IFERROR('Data Sheet'!K18/'Data Sheet'!K$17,0) -> 0
B8: Change in Inventory | C8: =IFERROR('Data Sheet'!B19/'Data Sheet'!B$17,0) -> 0 | D8: =IFERROR('Data Sheet'!C19/'Data Sheet'!C$17,0) -> 0 | E8: =IFERROR('Data Sheet'!D19/'Data Sheet'!D$17,0) -> 0 | F8: =IFERROR('Data Sheet'!E19/'Data Sheet'!E$17,0) -> 0 | G8: =IFERROR('Data Sheet'!F19/'Data Sheet'!F$17,0) -> 0 | H8: =IFERROR('Data Sheet'!G19/'Data Sheet'!G$17,0) -> 0 | I8: =IFERROR('Data Sheet'!H19/'Data Sheet'!H$17,0) -> 0 | J8: =IFERROR('Data Sheet'!I19/'Data Sheet'!I$17,0) -> 0 | ... L8: =IFERROR('Data Sheet'!K19/'Data Sheet'!K$17,0) -> 0
B9: Power and Fuel | C9: =IFERROR('Data Sheet'!B20/'Data Sheet'!B$17,0) -> 0.0033292448 | D9: =IFERROR('Data Sheet'!C20/'Data Sheet'!C$17,0) -> 0.0029352542 | E9: =IFERROR('Data Sheet'!D20/'Data Sheet'!D$17,0) -> 0.0026731176 | F9: =IFERROR('Data Sheet'!E20/'Data Sheet'!E$17,0) -> 0.0025222764 | G9: =IFERROR('Data Sheet'!F20/'Data Sheet'!F$17,0) -> 0.0014232821 | H9: =IFERROR('Data Sheet'!G20/'Data Sheet'!G$17,0) -> 0.0010851604 | I9: =IFERROR('Data Sheet'!H20/'Data Sheet'!H$17,0) -> 0.0011991797 | J9: =IFERROR('Data Sheet'!I20/'Data Sheet'!I$17,0) -> 0.0012949828 | ... L9: =IFERROR('Data Sheet'!K20/'Data Sheet'!K$17,0) -> 0.0012482508
B10: Other Mfr. Exp | C10: =IFERROR('Data Sheet'!B21/'Data Sheet'!B$17,0) -> 0.098008294 | D10: =IFERROR('Data Sheet'!C21/'Data Sheet'!C$17,0) -> 0.10331528 | E10: =IFERROR('Data Sheet'!D21/'Data Sheet'!D$17,0) -> 0.11977018 | F10: =IFERROR('Data Sheet'!E21/'Data Sheet'!E$17,0) -> 0.12210461 | G10: =IFERROR('Data Sheet'!F21/'Data Sheet'!F$17,0) -> 0.12739868 | H10: =IFERROR('Data Sheet'!G21/'Data Sheet'!G$17,0) -> 0.17009068 | I10: =IFERROR('Data Sheet'!H21/'Data Sheet'!H$17,0) -> 0.1794 | J10: =IFERROR('Data Sheet'!I21/'Data Sheet'!I$17,0) -> 0.17697013 | ... L10: =IFERROR('Data Sheet'!K21/'Data Sheet'!K$17,0) -> 0.18428212
B11: Employee Cost | C11: =IFERROR('Data Sheet'!B22/'Data Sheet'!B$17,0) -> 0.55004089 | D11: =IFERROR('Data Sheet'!C22/'Data Sheet'!C$17,0) -> 0.55162928 | E11: =IFERROR('Data Sheet'!D22/'Data Sheet'!D$17,0) -> 0.54820683 | F11: =IFERROR('Data Sheet'!E22/'Data Sheet'!E$17,0) -> 0.56057318 | G11: =IFERROR('Data Sheet'!F22/'Data Sheet'!F$17,0) -> 0.5528605 | H11: =IFERROR('Data Sheet'!G22/'Data Sheet'!G$17,0) -> 0.52611373 | I11: =IFERROR('Data Sheet'!H22/'Data Sheet'!H$17,0) -> 0.53400288 | J11: =IFERROR('Data Sheet'!I22/'Data Sheet'!I$17,0) -> 0.53774972 | ... L11: =IFERROR('Data Sheet'!K22/'Data Sheet'!K$17,0) -> 0.53239295
B12: Selling and admin | C12: =IFERROR('Data Sheet'!B23/'Data Sheet'!B$17,0) -> 0.066935343 | D12: =IFERROR('Data Sheet'!C23/'Data Sheet'!C$17,0) -> 0.065015173 | E12: =IFERROR('Data Sheet'!D23/'Data Sheet'!D$17,0) -> 0.067166616 | F12: =IFERROR('Data Sheet'!E23/'Data Sheet'!E$17,0) -> 0.059201903 | G12: =IFERROR('Data Sheet'!F23/'Data Sheet'!F$17,0) -> 0.031789951 | H12: =IFERROR('Data Sheet'!G23/'Data Sheet'!G$17,0) -> 0.035391028 | I12: =IFERROR('Data Sheet'!H23/'Data Sheet'!H$17,0) -> 0.03611166 | J12: =IFERROR('Data Sheet'!I23/'Data Sheet'!I$17,0) -> 0.037125008 | ... L12: =IFERROR('Data Sheet'!K23/'Data Sheet'!K$17,0) -> 0.037973692
B13: Other Expenses | C13: =IFERROR('Data Sheet'!B24/'Data Sheet'!B$17,0) -> 0.01003154 | D13: =IFERROR('Data Sheet'!C24/'Data Sheet'!C$17,0) -> 0.01020958 | E13: =IFERROR('Data Sheet'!D24/'Data Sheet'!D$17,0) -> 0.018215906 | F13: =IFERROR('Data Sheet'!E24/'Data Sheet'!E$17,0) -> 0.010342435 | G13: =IFERROR('Data Sheet'!F24/'Data Sheet'!F$17,0) -> 0.0089477665 | H13: =IFERROR('Data Sheet'!G24/'Data Sheet'!G$17,0) -> 0.0084346561 | I13: =IFERROR('Data Sheet'!H24/'Data Sheet'!H$17,0) -> 0.0099272997 | J13: =IFERROR('Data Sheet'!I24/'Data Sheet'!I$17,0) -> 0.0098262511 | ... L13: =IFERROR('Data Sheet'!K24/'Data Sheet'!K$17,0) -> 0.0074391268
B14: Other Income | C14: =IFERROR('Data Sheet'!B25/'Data Sheet'!B$17,0) -> 0.04453595 | D14: =IFERROR('Data Sheet'!C25/'Data Sheet'!C$17,0) -> 0.046949888 | E14: =IFERROR('Data Sheet'!D25/'Data Sheet'!D$17,0) -> 0.034859389 | F14: =IFERROR('Data Sheet'!E25/'Data Sheet'!E$17,0) -> 0.030873104 | G14: =IFERROR('Data Sheet'!F25/'Data Sheet'!F$17,0) -> 0.021906601 | H14: =IFERROR('Data Sheet'!G25/'Data Sheet'!G$17,0) -> 0.018866994 | I14: =IFERROR('Data Sheet'!H25/'Data Sheet'!H$17,0) -> 0.01840332 | J14: =IFERROR('Data Sheet'!I25/'Data Sheet'!I$17,0) -> 0.030656602 | ... L14: =IFERROR('Data Sheet'!K25/'Data Sheet'!K$17,0) -> 0.01697733
B15: Depreciation | C15: =IFERROR('Data Sheet'!B26/'Data Sheet'!B$17,0) -> 0.024867122 | D15: =IFERROR('Data Sheet'!C26/'Data Sheet'!C$17,0) -> 0.026417288 | E15: =IFERROR('Data Sheet'!D26/'Data Sheet'!D$17,0) -> 0.024324161 | F15: =IFERROR('Data Sheet'!E26/'Data Sheet'!E$17,0) -> 0.031864392 | G15: =IFERROR('Data Sheet'!F26/'Data Sheet'!F$17,0) -> 0.032516522 | H15: =IFERROR('Data Sheet'!G26/'Data Sheet'!G$17,0) -> 0.028575891 | I15: =IFERROR('Data Sheet'!H26/'Data Sheet'!H$17,0) -> 0.028787125 | J15: =IFERROR('Data Sheet'!I26/'Data Sheet'!I$17,0) -> 0.030441856 | ... L15: =IFERROR('Data Sheet'!K26/'Data Sheet'!K$17,0) -> 0.027439127
B16: Interest | C16: =IFERROR('Data Sheet'!B27/'Data Sheet'!B$17,0) -> 0 | D16: =IFERROR('Data Sheet'!C27/'Data Sheet'!C$17,0) -> 0 | E16: =IFERROR('Data Sheet'!D27/'Data Sheet'!D$17,0) -> 0 | F16: =IFERROR('Data Sheet'!E27/'Data Sheet'!E$17,0) -> 0.0018724323 | G16: =IFERROR('Data Sheet'!F27/'Data Sheet'!F$17,0) -> 0.0019408392 | H16: =IFERROR('Data Sheet'!G27/'Data Sheet'!G$17,0) -> 0.0016441825 | I16: =IFERROR('Data Sheet'!H27/'Data Sheet'!H$17,0) -> 0.0019350399 | J16: =IFERROR('Data Sheet'!I27/'Data Sheet'!I$17,0) -> 0.003058502 | ... L16: =IFERROR('Data Sheet'!K27/'Data Sheet'!K$17,0) -> 0.0023285754
B17: Profit before tax | C17: =IFERROR('Data Sheet'!B28/'Data Sheet'!B$17,0) -> 0.29132352 | D17: =IFERROR('Data Sheet'!C28/'Data Sheet'!C$17,0) -> 0.28742804 | E17: =IFERROR('Data Sheet'!D28/'Data Sheet'!D$17,0) -> 0.25450257 | F17: =IFERROR('Data Sheet'!E28/'Data Sheet'!E$17,0) -> 0.24239187 | G17: =IFERROR('Data Sheet'!F28/'Data Sheet'!F$17,0) -> 0.26502906 | H17: =IFERROR('Data Sheet'!G28/'Data Sheet'!G$17,0) -> 0.24753167 | I17: =IFERROR('Data Sheet'!H28/'Data Sheet'!H$17,0) -> 0.22704014 | J17: =IFERROR('Data Sheet'!I28/'Data Sheet'!I$17,0) -> 0.23419015 | ... L17: =IFERROR('Data Sheet'!K28/'Data Sheet'!K$17,0) -> 0.2238735
... B20: Dividend Amount | C20: =IFERROR('Data Sheet'!B31/'Data Sheet'!B$17,0) -> 0.086028853 | D20: =IFERROR('Data Sheet'!C31/'Data Sheet'!C$17,0) -> 0.13422194 | E20: =IFERROR('Data Sheet'!D31/'Data Sheet'!D$17,0) -> 0.11155125 | F20: =IFERROR('Data Sheet'!E31/'Data Sheet'!E$17,0) -> 0.081803262 | G20: =IFERROR('Data Sheet'!F31/'Data Sheet'!F$17,0) -> 0.11415718 | H20: =IFERROR('Data Sheet'!G31/'Data Sheet'!G$17,0) -> 0.10693434 | I20: =IFERROR('Data Sheet'!H31/'Data Sheet'!H$17,0) -> 0.095860786 | J20: =IFERROR('Data Sheet'!I31/'Data Sheet'!I$17,0) -> 0.12398777 | ... L20: =IFERROR('Data Sheet'!K31/'Data Sheet'!K$17,0) -> 0.10876238
B23: ="Common Size Balance Sheet"&"-"&'Data Sheet'!B1 -> Common Size Balance Sheet-INFOSYS LTD
B25: Particulars | C25: ='Data Sheet'!B16 -> 42825 | D25: ='Data Sheet'!C16 -> 43190 | E25: ='Data Sheet'!D16 -> 43555 | F25: ='Data Sheet'!E16 -> 43921 | G25: ='Data Sheet'!F16 -> 44286 | H25: ='Data Sheet'!G16 -> 44651 | I25: ='Data Sheet'!H16 -> 45016 | J25: ='Data Sheet'!I16 -> 45382 | ... L25: ='Data Sheet'!K16 -> 46112
B27: Equity Share Capital | C27: ='Historical FS'!C39/'Historical FS'!C$43 -> 0.013758599 | D27: ='Historical FS'!D39/'Historical FS'!D$43 -> 0.013711578 | E27: ='Historical FS'!E39/'Historical FS'!E$43 -> 0.025813052 | F27: ='Historical FS'!F39/'Historical FS'!F$43 -> 0.023115468 | G27: ='Historical FS'!G39/'Historical FS'!G$43 -> 0.019756118 | H27: ='Historical FS'!H39/'Historical FS'!H$43 -> 0.017973254 | I27: ='Historical FS'!I39/'Historical FS'!I$43 -> 0.01660567 | J27: ='Historical FS'!J39/'Historical FS'!J$43 -> 0.015225702 | ... L27: ='Historical FS'!L39/'Historical FS'!L$43 -> 0.013118324
B28: Reserves | C28: ='Historical FS'!C40/'Historical FS'!C$43 -> 0.8158705 | D28: ='Historical FS'!D40/'Historical FS'!D$43 -> 0.80448399 | E28: ='Historical FS'!E40/'Historical FS'!E$43 -> 0.74677039 | F28: ='Historical FS'!F40/'Historical FS'!F$43 -> 0.68984749 | G28: ='Historical FS'!G40/'Historical FS'!G$43 -> 0.69041307 | H28: ='Historical FS'!H40/'Historical FS'!H$43 -> 0.627539 | I28: ='Historical FS'!I40/'Historical FS'!I$43 -> 0.58860638 | J28: ='Historical FS'!J40/'Historical FS'!J$43 -> 0.6325908 | ... L28: ='Historical FS'!L40/'Historical FS'!L$43 -> 0.58869128
B29: Borrowings | C29: ='Historical FS'!C41/'Historical FS'!C$43 -> 0 | D29: ='Historical FS'!D41/'Historical FS'!D$43 -> 0 | E29: ='Historical FS'!E41/'Historical FS'!E$43 -> 0 | F29: ='Historical FS'!F41/'Historical FS'!F$43 -> 0.05046841 | G29: ='Historical FS'!G41/'Historical FS'!G$43 -> 0.049529816 | H29: ='Historical FS'!H41/'Historical FS'!H$43 -> 0.046894945 | I29: ='Historical FS'!I41/'Historical FS'!I$43 -> 0.066607275 | J29: ='Historical FS'!J41/'Historical FS'!J$43 -> 0.061454198 | ... L29: ='Historical FS'!L41/'Historical FS'!L$43 -> 0.059473193
B30: Other Liabilities | C30: ='Historical FS'!C42/'Historical FS'!C$43 -> 0.1703709 | D30: ='Historical FS'!D42/'Historical FS'!D$43 -> 0.18180443 | E30: ='Historical FS'!E42/'Historical FS'!E$43 -> 0.22741655 | F30: ='Historical FS'!F42/'Historical FS'!F$43 -> 0.23656863 | G30: ='Historical FS'!G42/'Historical FS'!G$43 -> 0.24030099 | H30: ='Historical FS'!H42/'Historical FS'!H$43 -> 0.3075928 | I30: ='Historical FS'!I42/'Historical FS'!I$43 -> 0.32818068 | J30: ='Historical FS'!J42/'Historical FS'!J$43 -> 0.2907293 | ... L30: ='Historical FS'!L42/'Historical FS'!L$43 -> 0.3387172
B31: Total liablities | C31: ='Historical FS'!C43/'Historical FS'!C$43 -> 1 | D31: ='Historical FS'!D43/'Historical FS'!D$43 -> 1 | E31: ='Historical FS'!E43/'Historical FS'!E$43 -> 1 | F31: ='Historical FS'!F43/'Historical FS'!F$43 -> 1 | G31: ='Historical FS'!G43/'Historical FS'!G$43 -> 1 | H31: ='Historical FS'!H43/'Historical FS'!H$43 -> 1 | I31: ='Historical FS'!I43/'Historical FS'!I$43 -> 1 | J31: ='Historical FS'!J43/'Historical FS'!J$43 -> 1 | ... L31: ='Historical FS'!L43/'Historical FS'!L$43 -> 1
B33: Fixed Assests Net Block | C33: ='Historical FS'!C45/'Historical FS'!C$56 -> 0.17052725 | D33: ='Historical FS'!D45/'Historical FS'!D$56 -> 0.1584645 | E33: ='Historical FS'!E45/'Historical FS'!E$56 -> 0.18687698 | F33: ='Historical FS'!F45/'Historical FS'!F$56 -> 0.25913943 | G33: ='Historical FS'!G45/'Historical FS'!G$56 -> 0.23723154 | H33: ='Historical FS'!H45/'Historical FS'!H$56 -> 0.22102477 | I33: ='Historical FS'!I45/'Historical FS'!I$56 -> 0.23455809 | J33: ='Historical FS'!J45/'Historical FS'!J$56 -> 0.20307308 | ... L33: ='Historical FS'!L45/'Historical FS'!L$56 -> 0.21887639
B34: Capital Work in Progress | C34: ='Historical FS'!C46/'Historical FS'!C$56 -> 0.01641651 | D34: ='Historical FS'!D46/'Historical FS'!D$56 -> 0.020239701 | E34: ='Historical FS'!E46/'Historical FS'!E$56 -> 0.016510837 | F34: ='Historical FS'!F46/'Historical FS'!F$56 -> 0.010392157 | G34: ='Historical FS'!G46/'Historical FS'!G$56 -> 0.0085758667 | H34: ='Historical FS'!H46/'Historical FS'!H$56 -> 0.0035638102 | I34: ='Historical FS'!I46/'Historical FS'!I$56 -> 0.0023114707 | J34: ='Historical FS'!J46/'Historical FS'!J$56 -> 0.002154095 | ... L34: ='Historical FS'!L46/'Historical FS'!L$56 -> 0.0034092088
B35: Investments | C35: ='Historical FS'!C47/'Historical FS'!C$56 -> 0.19751527 | D35: ='Historical FS'!D47/'Historical FS'!D$56 -> 0.15328486 | E35: ='Historical FS'!E47/'Historical FS'!E$56 -> 0.13395427 | F35: ='Historical FS'!F47/'Historical FS'!F$56 -> 0.09577342 | G35: ='Historical FS'!G47/'Historical FS'!G$56 -> 0.13212602 | H35: ='Historical FS'!H47/'Historical FS'!H$56 -> 0.17411269 | I35: ='Historical FS'!I47/'Historical FS'!I$56 -> 0.15632926 | J35: ='Historical FS'!J47/'Historical FS'!J$56 -> 0.18102485 | ... L35: ='Historical FS'!L47/'Historical FS'!L$56 -> 0.14181271
B36: Other Assets | C36: ='Historical FS'!C48/'Historical FS'!C$56 -> 0.19524222 | D36: ='Historical FS'!D48/'Historical FS'!D$56 -> 0.25263078 | E36: ='Historical FS'!E48/'Historical FS'!E$56 -> 0.2535151 | F36: ='Historical FS'!F48/'Historical FS'!F$56 -> 0.2301634 | G36: ='Historical FS'!G48/'Historical FS'!G$56 -> 0.21273172 | H36: ='Historical FS'!H48/'Historical FS'!H$56 -> 0.25716831 | I36: ='Historical FS'!I48/'Historical FS'!I$56 -> 0.30504992 | J36: ='Historical FS'!J48/'Historical FS'!J$56 -> 0.28306867 | ... L36: ='Historical FS'!L48/'Historical FS'!L$56 -> 0.26364332
B37: Total Non Current Assets | C37: ='Historical FS'!C49/'Historical FS'!C$56 -> 0.57970126 | D37: ='Historical FS'!D49/'Historical FS'!D$56 -> 0.58461984 | E37: ='Historical FS'!E49/'Historical FS'!E$56 -> 0.59085718 | F37: ='Historical FS'!F49/'Historical FS'!F$56 -> 0.59546841 | G37: ='Historical FS'!G49/'Historical FS'!G$56 -> 0.59066514 | H37: ='Historical FS'!H49/'Historical FS'!H$56 -> 0.65586958 | I37: ='Historical FS'!I49/'Historical FS'!I$56 -> 0.69824874 | J37: ='Historical FS'!J49/'Historical FS'!J$56 -> 0.66932069 | ... L37: ='Historical FS'!L49/'Historical FS'!L$56 -> 0.62774163
B39: Receivables | C39: ='Historical FS'!C51/'Historical FS'!C$56 -> 0.14819358 | D39: ='Historical FS'!D51/'Historical FS'!D$56 -> 0.16562276 | E39: ='Historical FS'!E51/'Historical FS'!E$56 -> 0.17637333 | F39: ='Historical FS'!F51/'Historical FS'!F$56 -> 0.20138344 | G39: ='Historical FS'!G51/'Historical FS'!G$56 -> 0.17946071 | H39: ='Historical FS'!H51/'Historical FS'!H$56 -> 0.19445039 | I39: ='Historical FS'!I51/'Historical FS'!I$56 -> 0.20405149 | J39: ='Historical FS'!J51/'Historical FS'!J$56 -> 0.22197471 | ... L39: ='Historical FS'!L51/'Historical FS'!L$56 -> 0.22836514
B40: Inventory | C40: ='Historical FS'!C52/'Historical FS'!C$56 -> 0 | D40: ='Historical FS'!D52/'Historical FS'!D$56 -> 0 | E40: ='Historical FS'!E52/'Historical FS'!E$56 -> 0 | F40: ='Historical FS'!F52/'Historical FS'!F$56 -> 0 | G40: ='Historical FS'!G52/'Historical FS'!G$56 -> 0 | H40: ='Historical FS'!H52/'Historical FS'!H$56 -> 0 | I40: ='Historical FS'!I52/'Historical FS'!I$56 -> 0 | J40: ='Historical FS'!J52/'Historical FS'!J$56 -> 0 | ... L40: ='Historical FS'!L52/'Historical FS'!L$56 -> 0
B41: Cash & Bank | C41: ='Historical FS'!C53/'Historical FS'!C$56 -> 0.27210516 | D41: ='Historical FS'!D53/'Historical FS'!D$56 -> 0.2497574 | E41: ='Historical FS'!E53/'Historical FS'!E$56 -> 0.23276949 | F41: ='Historical FS'!F53/'Historical FS'!F$56 -> 0.20314815 | G41: ='Historical FS'!G53/'Historical FS'!G$56 -> 0.22987415 | H41: ='Historical FS'!H53/'Historical FS'!H$56 -> 0.14968003 | I41: ='Historical FS'!I53/'Historical FS'!I$56 -> 0.097699766 | J41: ='Historical FS'!J53/'Historical FS'!J$56 -> 0.1087046 | ... L41: ='Historical FS'!L53/'Historical FS'!L$56 -> 0.14389324
B42: Total Current Assets | C42: ='Historical FS'!C54/'Historical FS'!C$56 -> 0.42029874 | D42: ='Historical FS'!D54/'Historical FS'!D$56 -> 0.41538016 | E42: ='Historical FS'!E54/'Historical FS'!E$56 -> 0.40914282 | F42: ='Historical FS'!F54/'Historical FS'!F$56 -> 0.40453159 | G42: ='Historical FS'!G54/'Historical FS'!G$56 -> 0.40933486 | H42: ='Historical FS'!H54/'Historical FS'!H$56 -> 0.34413042 | I42: ='Historical FS'!I54/'Historical FS'!I$56 -> 0.30175126 | J42: ='Historical FS'!J54/'Historical FS'!J$56 -> 0.33067931 | ... L42: ='Historical FS'!L54/'Historical FS'!L$56 -> 0.37225837
B44: Total Assets | C44: ='Historical FS'!C56/'Historical FS'!C$56 -> 1 | D44: ='Historical FS'!D56/'Historical FS'!D$56 -> 1 | E44: ='Historical FS'!E56/'Historical FS'!E$56 -> 1 | F44: ='Historical FS'!F56/'Historical FS'!F$56 -> 1 | G44: ='Historical FS'!G56/'Historical FS'!G$56 -> 1 | H44: ='Historical FS'!H56/'Historical FS'!H$56 -> 1 | I44: ='Historical FS'!I56/'Historical FS'!I$56 -> 1 | J44: ='Historical FS'!J56/'Historical FS'!J$56 -> 1 | ... L44: ='Historical FS'!L56/'Historical FS'!L$56 -> 1

Sheet Ratio analysis
B2: ="Ratio Analysis -"&'Data Sheet'!B1 -> Ratio Analysis -INFOSYS LTD
B3: Years | C3: ='Data Sheet'!B16 -> 42825 | D3: ='Data Sheet'!C16 -> 43190 | E3: ='Data Sheet'!D16 -> 43555 | F3: ='Data Sheet'!E16 -> 43921 | G3: ='Data Sheet'!F16 -> 44286 | H3: ='Data Sheet'!G16 -> 44651 | I3: ='Data Sheet'!H16 -> 45016 | J3: ='Data Sheet'!I16 -> 45382 | ... L3: ='Data Sheet'!K16 -> 46112 | M3: Trendlines | N3: Mean | O3: Median
B5: Sales growth | D5: =IFERROR('Historical FS'!D6/'Historical FS'!C6-1,0) -> 0.029758776 | E5: =IFERROR('Historical FS'!E6/'Historical FS'!D6-1,0) -> 0.1723292 | F5: =IFERROR('Historical FS'!F6/'Historical FS'!E6-1,0) -> 0.098167523 | G5: =IFERROR('Historical FS'!G6/'Historical FS'!F6-1,0) -> 0.10662951 | H5: =IFERROR('Historical FS'!H6/'Historical FS'!G6-1,0) -> 0.21069552 | I5: =IFERROR('Historical FS'!I6/'Historical FS'!H6-1,0) -> 0.20655864 | J5: =IFERROR('Historical FS'!J6/'Historical FS'!I6-1,0) -> 0.047033734 | K5: =IFERROR('Historical FS'!K6/'Historical FS'!J6-1,0) -> 0.060649444 | L5: =IFERROR('Historical FS'!L6/'Historical FS'!K6-1,0) -> 0.096079514 | N5: =IFERROR(AVERAGE(D5:L5),0) -> 0.11421132 | O5: =IFERROR(MEDIAN(D5:L5),0) -> 0.098167523
B6: EBITDA growth | D6: =IFERROR('Historical FS'!D14/'Historical FS'!C14-1,0) -> 0.01171791 | E6: =IFERROR('Historical FS'!E14/'Historical FS'!D14-1,0) -> 0.071618319 | F6: =IFERROR('Historical FS'!F14/'Historical FS'!E14-1,0) -> 0.10396629 | G6: =IFERROR('Historical FS'!G14/'Historical FS'!F14-1,0) -> 0.25248125 | H6: =IFERROR('Historical FS'!H14/'Historical FS'!G14-1,0) -> 0.12915486 | I6: =IFERROR('Historical FS'!I14/'Historical FS'!H14-1,0) -> 0.11555683 | J6: =IFERROR('Historical FS'!J14/'Historical FS'!I14-1,0) -> 0.03686308 | K6: =IFERROR('Historical FS'!K14/'Historical FS'!J14-1,0) -> 0.077172272 | L6: =IFERROR('Historical FS'!L14/'Historical FS'!K14-1,0) -> 0.077581813 | N6: =IFERROR(AVERAGE(D6:L6),0) -> 0.097345847 | O6: =IFERROR(MEDIAN(D6:L6),0) -> 0.077581813
B7: EBT growth | D7: =IFERROR('Historical FS'!D22/'Historical FS'!C22-1,0) -> 0.015989173 | E7: =IFERROR('Historical FS'!E22/'Historical FS'!D22-1,0) -> 0.038036507 | F7: =IFERROR('Historical FS'!F22/'Historical FS'!E22-1,0) -> 0.045910365 | G7: =IFERROR('Historical FS'!G22/'Historical FS'!F22-1,0) -> 0.20997864 | H7: =IFERROR('Historical FS'!H22/'Historical FS'!G22-1,0) -> 0.13076461 | I7: =IFERROR('Historical FS'!I22/'Historical FS'!H22-1,0) -> 0.10667552 | J7: =IFERROR('Historical FS'!J22/'Historical FS'!I22-1,0) -> 0.080007202 | K7: =IFERROR('Historical FS'!K22/'Historical FS'!J22-1,0) -> 0.045015005 | L7: =IFERROR('Historical FS'!L22/'Historical FS'!K22-1,0) -> 0.063470538 | N7: =IFERROR(AVERAGE(D7:L7),0) -> 0.081760841 | O7: =IFERROR(MEDIAN(D7:L7),0) -> 0.063470538
B8: Net profit growth | D8: =IFERROR('Historical FS'!D26/'Historical FS'!C26-1,0) -> 0.11677001 | E8: =IFERROR('Historical FS'!E26/'Historical FS'!D26-1,0) -> -0.038617506 | F8: =IFERROR('Historical FS'!F26/'Historical FS'!E26-1,0) -> 0.079753407 | G8: =IFERROR('Historical FS'!G26/'Historical FS'!F26-1,0) -> 0.16731775 | H8: =IFERROR('Historical FS'!H26/'Historical FS'!G26-1,0) -> 0.14019461 | I8: =IFERROR('Historical FS'!I26/'Historical FS'!H26-1,0) -> 0.088593877 | J8: =IFERROR('Historical FS'!J26/'Historical FS'!I26-1,0) -> 0.088767214 | K8: =IFERROR('Historical FS'!K26/'Historical FS'!J26-1,0) -> 0.019125267 | L8: =IFERROR('Historical FS'!L26/'Historical FS'!K26-1,0) -> 0.10183178 | N8: =IFERROR(AVERAGE(D8:L8),0) -> 0.084859601 | O8: =IFERROR(MEDIAN(D8:L8),0) -> 0.088767214
B9: Dividend growth | D9: =IFERROR('Historical FS'!D33/'Historical FS'!C33-1,0) -> 0.68963897 | E9: =IFERROR('Historical FS'!E33/'Historical FS'!D33-1,0) -> -0.02583858 | F9: =IFERROR('Historical FS'!F33/'Historical FS'!E33-1,0) -> -0.17390646 | G9: =IFERROR('Historical FS'!G33/'Historical FS'!F33-1,0) -> 0.54369512 | H9: =IFERROR('Historical FS'!H33/'Historical FS'!G33-1,0) -> 0.14865158 | I9: =IFERROR('Historical FS'!I33/'Historical FS'!H33-1,0) -> 0.096761529 | J9: =IFERROR('Historical FS'!J33/'Historical FS'!I33-1,0) -> 0.35349861 | K9: =IFERROR('Historical FS'!K33/'Historical FS'!J33-1,0) -> -0.064855345 | L9: =IFERROR('Historical FS'!L33/'Historical FS'!K33-1,0) -> 0.116149 | N9: =IFERROR(AVERAGE(D9:L9),0) -> 0.18708827 | O9: =IFERROR(MEDIAN(D9:L9),0) -> 0.116149
B11: Gross margin | C11: =IFERROR('Historical FS'!C11,0) -> 0.34862158 | D11: =IFERROR('Historical FS'!D11,0) -> 0.34212019 | E11: =IFERROR('Historical FS'!E11,0) -> 0.32934986 | F11: =IFERROR('Historical FS'!F11,0) -> 0.31479993 | G11: =IFERROR('Historical FS'!G11,0) -> 0.31831754 | H11: =IFERROR('Historical FS'!H11,0) -> 0.30271043 | I11: =IFERROR('Historical FS'!I11,0) -> 0.28539794 | J11: =IFERROR('Historical FS'!J11,0) -> 0.28398516 | ... L11: =IFERROR('Historical FS'!L11,0) -> 0.28207669 | N11: =IFERROR(AVERAGE(D11:L11),0) -> 0.30482983 | O11: =IFERROR(MEDIAN(D11:L11),0) -> 0.30271043
B12: EBITDA margin | C12: =IFERROR('Historical FS'!C15,0) -> 0.27165469 | D12: =IFERROR('Historical FS'!D15,0) -> 0.26689544 | E12: =IFERROR('Historical FS'!E15,0) -> 0.24396734 | F12: =IFERROR('Historical FS'!F15,0) -> 0.24525559 | G12: =IFERROR('Historical FS'!G15,0) -> 0.27757982 | H12: =IFERROR('Historical FS'!H15,0) -> 0.25888475 | I12: =IFERROR('Historical FS'!I15,0) -> 0.23935898 | J12: =IFERROR('Historical FS'!J15,0) -> 0.2370339 | ... L12: =IFERROR('Historical FS'!L15,0) -> 0.23666387 | N12: =IFERROR(AVERAGE(D12:L12),0) -> 0.24959624 | O12: =IFERROR(MEDIAN(D12:L12),0) -> 0.24396734
B13: EBIT margin | C13: =IFERROR(('Historical FS'!C14-'Historical FS'!C18)/'Historical FS'!C6,) -> 0.24678757 | D13: =IFERROR(('Historical FS'!D14-'Historical FS'!D18)/'Historical FS'!D6,) -> 0.24047815 | E13: =IFERROR(('Historical FS'!E14-'Historical FS'!E18)/'Historical FS'!E6,) -> 0.21964318 | F13: =IFERROR(('Historical FS'!F14-'Historical FS'!F18)/'Historical FS'!F6,) -> 0.2133912 | G13: =IFERROR(('Historical FS'!G14-'Historical FS'!G18)/'Historical FS'!G6,) -> 0.2450633 | H13: =IFERROR(('Historical FS'!H14-'Historical FS'!H18)/'Historical FS'!H6,) -> 0.23030886 | I13: =IFERROR(('Historical FS'!I14-'Historical FS'!I18)/'Historical FS'!I6,) -> 0.21057186 | J13: =IFERROR(('Historical FS'!J14-'Historical FS'!J18)/'Historical FS'!J6,) -> 0.20659205 | ... L13: =IFERROR(('Historical FS'!L14-'Historical FS'!L18)/'Historical FS'!L6,) -> 0.20922474 | N13: =IFERROR(AVERAGE(D13:L13),0) -> 0.22071961 | O13: =IFERROR(MEDIAN(D13:L13),0) -> 0.2133912
B14: EBT margin | C14: =IFERROR('Historical FS'!C23,0) -> 0.29132352 | D14: =IFERROR('Historical FS'!D23,0) -> 0.28742804 | E14: =IFERROR('Historical FS'!E23,0) -> 0.25450257 | F14: =IFERROR('Historical FS'!F23,0) -> 0.24239187 | G14: =IFERROR('Historical FS'!G23,0) -> 0.26502906 | H14: =IFERROR('Historical FS'!H23,0) -> 0.24753167 | I14: =IFERROR('Historical FS'!I23,0) -> 0.22704014 | J14: =IFERROR('Historical FS'!J23,0) -> 0.23419015 | ... L14: =IFERROR('Historical FS'!L23,0) -> 0.2238735 | N14: =IFERROR(AVERAGE(D14:L14),0) -> 0.24585834 | O14: =IFERROR(MEDIAN(D14:L14),0) -> 0.24239187
B15: Net profit margin | C15: =IFERROR('Historical FS'!C27,0) -> 0.2095818 | D15: =IFERROR('Historical FS'!D27,0) -> 0.22729077 | E15: =IFERROR('Historical FS'!E27,0) -> 0.1863925 | F15: =IFERROR('Historical FS'!F27,0) -> 0.18326706 | G15: =IFERROR('Historical FS'!G27,0) -> 0.19331754 | H15: =IFERROR('Historical FS'!H27,0) -> 0.18206033 | I15: =IFERROR('Historical FS'!I27,0) -> 0.16426036 | J15: =IFERROR('Historical FS'!J27,0) -> 0.17080757 | ... L15: =IFERROR('Historical FS'!L27,0) -> 0.16498181 | N15: =IFERROR(AVERAGE(D15:L15),0) -> 0.18183316 | O15: =IFERROR(MEDIAN(D15:L15),0) -> 0.18206033
B17: Sales expense% sales | C17: =IFERROR('Historical FS'!C12/'Historical FS'!C6,0) -> 0.076966883 | D17: =IFERROR('Historical FS'!D12/'Historical FS'!D6,0) -> 0.075224753 | E17: =IFERROR('Historical FS'!E12/'Historical FS'!E6,0) -> 0.085382522 | F17: =IFERROR('Historical FS'!F12/'Historical FS'!F6,0) -> 0.069544338 | G17: =IFERROR('Historical FS'!G12/'Historical FS'!G6,0) -> 0.040737718 | H17: =IFERROR('Historical FS'!H12/'Historical FS'!H6,0) -> 0.043825684 | I17: =IFERROR('Historical FS'!I12/'Historical FS'!I6,0) -> 0.04603896 | J17: =IFERROR('Historical FS'!J12/'Historical FS'!J6,0) -> 0.046951259 | ... L17: =IFERROR('Historical FS'!L12/'Historical FS'!L6,0) -> 0.045412818 | N17: =IFERROR(AVERAGE(D17:L17),0) -> 0.055233594 | O17: =IFERROR(MEDIAN(D17:L17),0) -> 0.04603896
B18: Depreciation% sales | C18: =IFERROR('Historical FS'!C19,0) -> 0.024867122 | D18: =IFERROR('Historical FS'!D19,0) -> 0.026417288 | E18: =IFERROR('Historical FS'!E19,0) -> 0.024324161 | F18: =IFERROR('Historical FS'!F19,0) -> 0.031864392 | G18: =IFERROR('Historical FS'!G19,0) -> 0.032516522 | H18: =IFERROR('Historical FS'!H19,0) -> 0.028575891 | I18: =IFERROR('Historical FS'!I19,0) -> 0.028787125 | J18: =IFERROR('Historical FS'!J19,0) -> 0.030441856 | ... L18: =IFERROR('Historical FS'!L19,0) -> 0.027439127 | N18: =IFERROR(AVERAGE(D18:L18),0) -> 0.028876627 | O18: =IFERROR(MEDIAN(D18:L18),0) -> 0.028787125
B19: Operating income% sales | C19: =IFERROR('Ratio analysis'!C13,0) -> 0.24678757 | D19: =IFERROR('Ratio analysis'!D13,0) -> 0.24047815 | E19: =IFERROR('Ratio analysis'!E13,0) -> 0.21964318 | F19: =IFERROR('Ratio analysis'!F13,0) -> 0.2133912 | G19: =IFERROR('Ratio analysis'!G13,0) -> 0.2450633 | H19: =IFERROR('Ratio analysis'!H13,0) -> 0.23030886 | I19: =IFERROR('Ratio analysis'!I13,0) -> 0.21057186 | J19: =IFERROR('Ratio analysis'!J13,0) -> 0.20659205 | ... L19: =IFERROR('Ratio analysis'!L13,0) -> 0.20922474 | N19: =IFERROR(AVERAGE(D19:L19),0) -> 0.22071961 | O19: =IFERROR(MEDIAN(D19:L19),0) -> 0.2133912
B21: Return on capital employed | C21: =IFERROR(('Historical FS'!C14-'Historical FS'!C18)/SUM('Historical FS'!C39:C41),0) -> 0.24500594 | D21: =IFERROR(('Historical FS'!D14-'Historical FS'!D18)/SUM('Historical FS'!D39:D41),0) -> 0.26121713 | E21: =IFERROR(('Historical FS'!E14-'Historical FS'!E18)/SUM('Historical FS'!E39:E41),0) -> 0.27959291 | F21: =IFERROR(('Historical FS'!F14-'Historical FS'!F18)/SUM('Historical FS'!F39:F41),0) -> 0.27644365 | G21: =IFERROR(('Historical FS'!G14-'Historical FS'!G18)/SUM('Historical FS'!G39:G41),0) -> 0.30145943 | H21: =IFERROR(('Historical FS'!H14-'Historical FS'!H18)/SUM('Historical FS'!H39:H41),0) -> 0.34661734 | I21: =IFERROR(('Historical FS'!I14-'Historical FS'!I18)/SUM('Historical FS'!I39:I41),0) -> 0.3692089 | J21: =IFERROR(('Historical FS'!J14-'Historical FS'!J18)/SUM('Historical FS'!J39:J41),0) -> 0.32906971 | ... L21: =IFERROR(('Historical FS'!L14-'Historical FS'!L18)/SUM('Historical FS'!L39:L41),0) -> 0.36635041 | N21: =IFERROR(AVERAGE(D21:L21),0) -> 0.31786848 | O21: =IFERROR(MEDIAN(D21:L21),0) -> 0.32906971
B22: Retained earning | C22: =IFERROR('Historical FS'!C35,0) -> 0.58952135 | D22: =IFERROR('Historical FS'!D35,0) -> 0.40947034 | E22: =IFERROR('Historical FS'!E35,0) -> 0.40152498 | F22: =IFERROR('Historical FS'!F35,0) -> 0.55363904 | G22: =IFERROR('Historical FS'!G35,0) -> 0.4094836 | H22: =IFERROR('Historical FS'!H35,0) -> 0.41264337 | I22: =IFERROR('Historical FS'!I35,0) -> 0.41640949 | J22: =IFERROR('Historical FS'!J35,0) -> 0.2741085 | ... L22: =IFERROR('Historical FS'!L35,0) -> 0.34076135 | N22: =IFERROR(AVERAGE(D22:L22),0) -> 0.3946201 | O22: =IFERROR(MEDIAN(D22:L22),0) -> 0.40947034
B23: Return on equity% | C23: =IFERROR('Historical FS'!C26/SUM('Historical FS'!C39:C40),) -> 0.20806877 | D23: =IFERROR('Historical FS'!D26/SUM('Historical FS'!D39:D40),) -> 0.24689247 | E23: =IFERROR('Historical FS'!E26/SUM('Historical FS'!E39:E40),) -> 0.23726674 | F23: =IFERROR('Historical FS'!F26/SUM('Historical FS'!F39:F40),) -> 0.2542246 | G23: =IFERROR('Historical FS'!G26/SUM('Historical FS'!G39:G40),) -> 0.25439091 | H23: =IFERROR('Historical FS'!H26/SUM('Historical FS'!H39:H40),) -> 0.29390843 | I23: =IFERROR('Historical FS'!I26/SUM('Historical FS'!I39:I40),) -> 0.31970507 | J23: =IFERROR('Historical FS'!J26/SUM('Historical FS'!J39:J40),) -> 0.29788007 | ... L23: =IFERROR('Historical FS'!L26/SUM('Historical FS'!L39:L40),) -> 0.31742989 | N23: =IFERROR(AVERAGE(D23:L23),0) -> 0.27787481 | O23: =IFERROR(MEDIAN(D23:L23),0) -> 0.2791751
B24: Self sustained growth rate | C24: =C22*C23 -> 0.12266098 | D24: =D22*D23 -> 0.10109514 | E24: =E22*E23 -> 0.095268523 | F24: =F22*F23 -> 0.14074866 | G24: =G22*G23 -> 0.1041689 | H24: =H22*H23 -> 0.12127936 | I24: =I22*I23 -> 0.13312822 | J24: =J22*J23 -> 0.081651459 | ... L24: =L22*L23 -> 0.10816784 | N24: =IFERROR(AVERAGE(D24:L24),0) -> 0.10873603 | O24: =IFERROR(MEDIAN(D24:L24),0) -> 0.1041689
B25: Interest coverage ratio | C25: =IFERROR(('Historical FS'!C14-'Historical FS'!C18)/'Historical FS'!C20,0) -> 0 | D25: =IFERROR(('Historical FS'!D14-'Historical FS'!D18)/'Historical FS'!D20,0) -> 0 | E25: =IFERROR(('Historical FS'!E14-'Historical FS'!E18)/'Historical FS'!E20,0) -> 0 | F25: =IFERROR(('Historical FS'!F14-'Historical FS'!F18)/'Historical FS'!F20,0) -> 113.96471 | G25: =IFERROR(('Historical FS'!G14-'Historical FS'!G18)/'Historical FS'!G20,0) -> 126.26667 | H25: =IFERROR(('Historical FS'!H14-'Historical FS'!H18)/'Historical FS'!H20,0) -> 140.075 | I25: =IFERROR(('Historical FS'!I14-'Historical FS'!I18)/'Historical FS'!I20,0) -> 108.82042 | J25: =IFERROR(('Historical FS'!J14-'Historical FS'!J18)/'Historical FS'!J20,0) -> 67.546809 | ... L25: =IFERROR(('Historical FS'!L14-'Historical FS'!L18)/'Historical FS'!L20,0) -> 89.850962 | N25: =IFERROR(AVERAGE(D25:L25),0) -> 81.030507 | O25: =IFERROR(MEDIAN(D25:L25),0) -> 89.850962
B27: Debtor turnover ratio | C27: =IFERROR('Historical FS'!C6/'Historical FS'!C51,0) -> 5.557864 | D27: =IFERROR('Historical FS'!D6/'Historical FS'!D51,0) -> 5.3661543 | E27: =IFERROR('Historical FS'!E6/'Historical FS'!E51,0) -> 5.5759763 | F27: =IFERROR('Historical FS'!F6/'Historical FS'!F51,0) -> 4.9110726 | G27: =IFERROR('Historical FS'!G6/'Historical FS'!G51,0) -> 5.207422 | H27: =IFERROR('Historical FS'!H6/'Historical FS'!H51,0) -> 5.3591065 | I27: =IFERROR('Historical FS'!I6/'Historical FS'!I51,0) -> 5.7727738 | J27: =IFERROR('Historical FS'!J6/'Historical FS'!J51,0) -> 5.0895903 | ... L27: =IFERROR('Historical FS'!L6/'Historical FS'!L51,0) -> 5.0703866 | N27: =IFERROR(AVERAGE(D27:L27),0) -> 5.2870625 | O27: =IFERROR(MEDIAN(D27:L27),0) -> 5.2310803
B28: Creditor turnover ratio | C28: =IFERROR('Historical FS'!C6/'Historical FS'!C41,0) -> 0 | D28: =IFERROR('Historical FS'!D6/'Historical FS'!D41,0) -> 0 | E28: =IFERROR('Historical FS'!E6/'Historical FS'!E41,0) -> 0 | F28: =IFERROR('Historical FS'!F6/'Historical FS'!F41,0) -> 19.59659 | G28: =IFERROR('Historical FS'!G6/'Historical FS'!G41,0) -> 18.867981 | H28: =IFERROR('Historical FS'!H6/'Historical FS'!H41,0) -> 22.221593 | I28: =IFERROR('Historical FS'!I6/'Historical FS'!I41,0) -> 17.684902 | J28: =IFERROR('Historical FS'!J6/'Historical FS'!J41,0) -> 18.383778 | ... L28: =IFERROR('Historical FS'!L6/'Historical FS'!L41,0) -> 19.469268 | N28: =IFERROR(AVERAGE(D28:L28),0) -> 15.115079 | O28: =IFERROR(MEDIAN(D28:L28),0) -> 18.867981
B29: Inventory turnover ratio | C29: =IFERROR('Historical FS'!C6/'Historical FS'!C52,0) -> 0 | D29: =IFERROR('Historical FS'!D6/'Historical FS'!D52,0) -> 0 | E29: =IFERROR('Historical FS'!E6/'Historical FS'!E52,0) -> 0 | F29: =IFERROR('Historical FS'!F6/'Historical FS'!F52,0) -> 0 | G29: =IFERROR('Historical FS'!G6/'Historical FS'!G52,0) -> 0 | H29: =IFERROR('Historical FS'!H6/'Historical FS'!H52,0) -> 0 | I29: =IFERROR('Historical FS'!I6/'Historical FS'!I52,0) -> 0 | J29: =IFERROR('Historical FS'!J6/'Historical FS'!J52,0) -> 0 | ... L29: =IFERROR('Historical FS'!L6/'Historical FS'!L52,0) -> 0 | N29: =IFERROR(AVERAGE(D29:L29),0) -> 0 | O29: =IFERROR(MEDIAN(D29:L29),0) -> 0
B30: Fixed asset turnover ratio | C30: =IFERROR('Historical FS'!C6/'Historical FS'!C45,0) -> 4.8299598 | D30: =IFERROR('Historical FS'!D6/'Historical FS'!D45,0) -> 5.6085573 | E30: =IFERROR('Historical FS'!E6/'Historical FS'!E45,0) -> 5.2625716 | F30: =IFERROR('Historical FS'!F6/'Historical FS'!F45,0) -> 3.8165118 | G30: =IFERROR('Historical FS'!G6/'Historical FS'!G45,0) -> 3.939306 | H30: =IFERROR('Historical FS'!H6/'Historical FS'!H45,0) -> 4.7147674 | I30: =IFERROR('Historical FS'!I6/'Historical FS'!I45,0) -> 5.0219675 | J30: =IFERROR('Historical FS'!J6/'Historical FS'!J45,0) -> 5.5633191 | ... L30: =IFERROR('Historical FS'!L6/'Historical FS'!L45,0) -> 5.2901984 | N30: =IFERROR(AVERAGE(D30:L30),0) -> 4.942396 | O30: =IFERROR(MEDIAN(D30:L30),0) -> 5.2625716
B31: Capital turnover ratio | C31: =IFERROR('Historical FS'!C6/SUM('Historical FS'!C39:C40),0) -> 0.99278073 | D31: =IFERROR('Historical FS'!D6/SUM('Historical FS'!D39:D40),0) -> 1.0862406 | E31: =IFERROR('Historical FS'!E6/SUM('Historical FS'!E39:E40),0) -> 1.2729414 | F31: =IFERROR('Historical FS'!F6/SUM('Historical FS'!F39:F40),0) -> 1.3871811 | G31: =IFERROR('Historical FS'!G6/SUM('Historical FS'!G39:G40),0) -> 1.3159225 | H31: =IFERROR('Historical FS'!H6/SUM('Historical FS'!H39:H40),0) -> 1.6143464 | I31: =IFERROR('Historical FS'!I6/SUM('Historical FS'!I39:I40),0) -> 1.9463312 | J31: =IFERROR('Historical FS'!J6/SUM('Historical FS'!J39:J40),0) -> 1.7439512 | ... L31: =IFERROR('Historical FS'!L6/SUM('Historical FS'!L39:L40),0) -> 1.9240296 | N31: =IFERROR(AVERAGE(D31:L31),0) -> 1.5546646 | O31: =IFERROR(MEDIAN(D31:L31),0) -> 1.6143464
B33: Debtor days | C33: =IFERROR(365/C27,0) -> 65.672712 | D33: =IFERROR(365/D27,0) -> 68.018916 | E33: =IFERROR(365/E27,0) -> 65.459389 | F33: =IFERROR(365/F27,0) -> 74.321849 | G33: =IFERROR(365/G27,0) -> 70.092265 | H33: =IFERROR(365/H27,0) -> 68.108368 | I33: =IFERROR(365/I27,0) -> 63.227837 | J33: =IFERROR(365/J27,0) -> 71.715006 | ... L33: =IFERROR(365/L27,0) -> 71.986622 | N33: =IFERROR(AVERAGE(D33:L33),0) -> 69.189502 | O33: =IFERROR(MEDIAN(D33:L33),0) -> 69.775262
B34: Payable days | C34: =IFERROR(365/C28,0) -> 0 | D34: =IFERROR(365/D28,0) -> 0 | E34: =IFERROR(365/E28,0) -> 0 | F34: =IFERROR(365/F28,0) -> 18.62569 | G34: =IFERROR(365/G28,0) -> 19.344942 | H34: =IFERROR(365/H28,0) -> 16.425465 | I34: =IFERROR(365/I28,0) -> 20.639074 | J34: =IFERROR(365/J28,0) -> 19.854461 | ... L34: =IFERROR(365/L28,0) -> 18.747495 | N34: =IFERROR(AVERAGE(D34:L34),0) -> 14.673409 | O34: =IFERROR(MEDIAN(D34:L34),0) -> 18.62569
B35: Inventory days | C35: =IFERROR(365/C29,0) -> 0 | D35: =IFERROR(365/D29,0) -> 0 | E35: =IFERROR(365/E29,0) -> 0 | F35: =IFERROR(365/F29,0) -> 0 | G35: =IFERROR(365/G29,0) -> 0 | H35: =IFERROR(365/H29,0) -> 0 | I35: =IFERROR(365/I29,0) -> 0 | J35: =IFERROR(365/J29,0) -> 0 | ... L35: =IFERROR(365/L29,0) -> 0 | N35: =IFERROR(AVERAGE(D35:L35),0) -> 0 | O35: =IFERROR(MEDIAN(D35:L35),0) -> 0
B36: Cash conversion | C36: =SUM(C33,C35)-C34 -> 65.672712 | D36: =SUM(D33,D35)-D34 -> 68.018916 | E36: =SUM(E33,E35)-E34 -> 65.459389 | F36: =SUM(F33,F35)-F34 -> 55.696159 | G36: =SUM(G33,G35)-G34 -> 50.747323 | H36: =SUM(H33,H35)-H34 -> 51.682903 | I36: =SUM(I33,I35)-I34 -> 42.588763 | J36: =SUM(J33,J35)-J34 -> 51.860545 | ... L36: =SUM(L33,L35)-L34 -> 53.239127 | N36: =IFERROR(AVERAGE(D36:L36),0) -> 54.516093 | O36: =IFERROR(MEDIAN(D36:L36),0) -> 51.860545
B38: CFO/sales | C38: =IFERROR('Historical FS'!C62/'Historical FS'!C6,0) -> 0.16837509 | D38: =IFERROR('Historical FS'!D62/'Historical FS'!D6,0) -> 0.18743087 | E38: =IFERROR('Historical FS'!E62/'Historical FS'!E6,0) -> 0.17951013 | F38: =IFERROR('Historical FS'!F62/'Historical FS'!F6,0) -> 0.18727627 | G38: =IFERROR('Historical FS'!G62/'Historical FS'!G6,0) -> 0.23114898 | H38: =IFERROR('Historical FS'!H62/'Historical FS'!H6,0) -> 0.19635649 | I38: =IFERROR('Historical FS'!I62/'Historical FS'!I6,0) -> 0.15307937 | J38: =IFERROR('Historical FS'!J62/'Historical FS'!J6,0) -> 0.16405284 | ... L38: =IFERROR('Historical FS'!L62/'Historical FS'!L6,0) -> 0.1902379 | N38: =IFERROR(AVERAGE(D38:L38),0) -> 0.18978754 | O38: =IFERROR(MEDIAN(D38:L38),0) -> 0.18743087
